Workbook
Name \P: #REF!
Name _Principal: #REF!
Name _Sr2: "Sr2"
Name abc: #N/A
Name AccountTotal1: #REF!
Name AccountTotal2: #REF!
Name AccountTotal3: #REF!
Name AccountTotal4: #REF!
Name AccountTotal5: #REF!
Name AccountTotal6: #REF!
Name AccountTotal7: #REF!
Name AccountTotal8: #REF!
Name AccountTotal9: #REF!
Name AcctTotal: #REF!
Name ACPAAfter: #REF!
Name ACPABefore: #REF!
Name act_360: 2
Name Actual12moChargeoffRatio: #REF!
Name Actual3moChargeoffRatio: #REF!
Name Actual3moDefaultRatio: #REF!
Name Add_Backs_10_50MM: #REF!
Name Add_Backs_10_50MM: 'Concentration Limits'!#REF!
Name Add_Backs_10MM: #REF!
Name Add_Backs_10MM: 'Concentration Limits'!#REF!
Name Add_Backs_50MM: #REF!
Name Add_Backs_50MM: 'Concentration Limits'!#REF!
Name Addend1: #REF!
Name addend1_AIF: #REF!
Name Addend2: #REF!
Name addend2_AIF: #REF!
Name Addend3: #REF!
Name addend3_AIF: #REF!
Name Addend4: #REF!
Name addend4_AIF: #REF!
Name adecco2: #N/A
Name AdjAdvRate: #REF!
Name AdvancesOS: #REF!
Name AfterTrade: #REF!
Name AggNetMarkMktAmount: #REF!
Name AgingsDetail: #REF!
Name Amounts: OFFSET(#REF!,,,40-COUNTBLANK(#REF!))
Name Anchor: #REF!
Name Angle: #REF!
Name Annual: "Annual"
Name AOLB: #REF!
Name AOLBrange: #REF!
Name AOPBAfter: #REF!
Name as: #REF!
Name asset_step_up_coupon: #REF!
Name AssetCoverageRatio: #REF!
Name AssetDataAfter: #REF!
Name AssetType: #REF!
Name Availablecapitalization: #REF!
Name AvailableClassCsec: #REF!
Name AvailableCollections: #REF!
Name AverageParAfter: #REF!
Name avg_commitment_fee: #REF!
Name avg_coupon_floaters: #REF!
Name avg_life_floaters: #REF!
Name avg_price_floaters: #REF!

Sheet Availability
B3: Borrower: | F3: Star Mountain Lower Middle-Market Capital Corp.
B5: Effective Date: | F5: 46022
B6: Scheduled Revolving Period End Date: | F6: 46570
B7: Termination Date: | F7: 46934
B8: Measurement Date | F8: 46022
B9: Interest Payment Date: | F9: N/A
B10: Advance Date: | F10: N/A
L13: BORROWER INPUTS
B15: PRO FORMA BORROWING BASE
B16: Facility Amount | L16: 200000000
B18: Cash on deposit in Principal Collection Account | L18: 5470977.5
B19: Interest Reserve Amount | L19: 0
B21: Availability is defined as the least of:
C22: (a) | D22: the Maximum Facility Amount | L22: =L16 -> 200000000
C23: (b) | D23: (a) the product of (x) the Borrowing Base multiplied by (y) the Weighted Average Advance Rate, minus (b) the Aggregate Unfunded Exposure Equity Amount, minus (c) the Interest Reserve Amount, plus (d) the amount of Available Collections on deposit in the Principal Collection Account as of such date | L23: =L35*L48-L37-L19+L18 -> 1.4708876e+08
C25: (c) | D25: (a) the aggregate Adjusted Borrowing Value of all Eligible Loan Assets as of such date minus (b) the Minimum Credit Enhancement Amount, plus (c) the amount of Available Collections on deposit in the Principal Collection Account as of such date, minus (d) the Aggregate Unfunded Exposure Equity Amount, minus (e) the Interest Reserve Amount | L25: =L33-L41+L18-L37-L19 -> 1.8685824e+08
C26: The least of (a), (b) and (c) | L26: =MIN(L22,L23,L25) -> 1.4708876e+08
K28: Effective Advance Rate | L28: =L26/L31 -> 0.44541148
K29: Effective Debt to Equity | L29: =L28/(1-L28) -> 0.80313866
N30: Commitments/Outstandings ($mm)
B31: Par value of portfolio | L31: =Portfolio!Y61 -> 3.3023119e+08 | P31: Comm. % | Q31: Commitment | R31: Outstanding
N32: Webster Bank | P32: =Q32/$Q$40 -> 0.3375 | Q32: 67500000 | R32: =P32*$L$54 -> 41276250
B33: Aggregate Adjusted Borrowing Value of Eligible Loans | L33: =Portfolio!V61 -> 2.329967e+08 | N33: Dime Community Bank | P33: =Q33/$Q$40 -> 0.125 | Q33: 25000000 | R33: =P33*$L$54 -> 15287500
B34: Less any Excess Concentrations | L34: ='Concentration Limits'!M44 -> 2295693 | N34: Woodforest National Bank | P34: =Q34/$Q$40 -> 0.1 | Q34: 20000000 | R34: =P34*$L$54 -> 12230000
B35: Adjusted Borrowing Value of Eligible Loans (Aggregate Adjusted Borrowing Value of Eligible Loans less Excess Concentration Amounts) | L35: =L33-L34 -> 2.3070101e+08 | N35: First Foundation Bank | P35: =Q35/$Q$40 -> 0.1 | Q35: 20000000 | R35: =P35*$L$54 -> 12230000
N36: Mitsubishi HC Capital America, Inc. | P36: =Q36/$Q$40 -> 0.1 | Q36: 20000000 | R36: =P36*$L$54 -> 12230000
B37: Unfunded Exposure Equity Amount | L37: {=SUMPRODUCT(Portfolio!AB9:AB59,--(Portfolio!BU9:BU59="Yes"))-SUMPRODUCT(Portfolio!AB9:AB59,--(Portfolio!BU9:BU59="Yes"),Portfolio!AL9:AL59,Portfolio!U9:U59)} -> 0 | N37: Peapack-Gladstone Bank | P37: =Q37/$Q$40 -> 0.085 | Q37: 17000000 | R37: =P37*$L$54 -> 10395500
B38: Unfunded Exposure Amount | L38: =SUMIF(Portfolio!$BU$9:$BU$98,"Yes",Portfolio!$A$9:$A$98) -> 0 | N38: Hanmi Bank | P38: =Q38/$Q$40 -> 0.0775 | Q38: 15500000 | R38: =P38*$L$54 -> 9478250
N39: Apple Bank | P39: =Q39/$Q$40 -> 0.075 | Q39: 15000000 | R39: =P39*$L$54 -> 9172500
N40: Total | P40: =SUM(P32:P39) -> 1 | Q40: =SUM(Q32:Q39) -> 200000000 | R40: =SUM(R32:R39) -> 122300000
B41: Minimum Equity | L41: =MAX(15000000,(LARGE(Portfolio!FJ:FJ,1)+LARGE(Portfolio!FJ:FJ,2)+LARGE(Portfolio!FJ:FJ,3))) -> 51609436
L42: =IF((L31-L26)>L41,"Pass") -> Pass
R43: 5000000
B48: Weighted Average Advance Rate | L48: =MIN('Concentration Limits'!G38,_xlfn.IFS('Concentration Limits'!G34<'Concentration Limits'!F35,Cap_1,AND('Concentration Limits'!G34>='Concentration Limits'!F35,'Concentration Limits'!G34<'Concentration Limits'!F37),Cap_2,'Concentration Limits'!G34>='Concentration Limits'!F37,Cap_3)) -> 0.61385854
B50: MAXIMUM ADVANCE RATE TEST AND UTILIZATION
B51: Current Advances Outstanding | L51: 122300000
B52: Advances Repaid
B53: Advances Requested
B54: Pro Forma Advances Outstanding | L54: =L51-L52+L53 -> 122300000
B56: Maximum Advance Rate Test | L56: =L26>=L54 -> TRUE
...

Sheet Portfolio
AG3: VAE : Historical Value(s) | AM3: Leverage Metrics: First Lien | AS3: Leverage Metrics: FILO | AY3: Leverage Metrics: Other loans | EK3: =SUM(EK9:EK20) -> 62238488
B4: AGENT INPUTS | DU4: Value Adjustment Events
A5: smc | B5: BORROWER INPUTS | BN5: Based on at time of origination or acquisition | CK5: Initial EBITDA (in $MM) | CU5: Current EBITDA (in $MM) | CZ5: Initial Net Debt in $ and Multiple Based on Permitted EBITDA | DF5: Current Net Debt in $ and Multiple Based on Permitted EBITDA | DO5: Interest Coverage | DU5: (a) Credit Quality Deterioration Events | DX5: (b) | DY5: (c) | DZ5: (d) Material Modification | EG5: (e) | EH5: (f) | EL5: 1) Max Second lien and FILO with senior lev in front of SMC >= 1.50x | EQ5: 1)b Max Second Lien Loans | EU5: 2) Max Non-First Lien (Second Lien and FILO with Senior Lev in front of SMC > 1.00x) | EZ5: 3) Max EBITDA < $5MM | FH5: 4) Largest Obligor | FR5: 5) Largest Industry | FW5: 2nd Largest Industry | GB5: All Other Industry Classifications | GG5: 6) Fixed Rate | GK5: 7) Max limit industry | GP5: 8) Max DDTL and Revolver | GU5: 9)a Max Non-Sponsor/Non-Family Office | GZ5: 9)b Max Div Recap for Non-Sponsor/Non-Family Office
DU6: (i) | DV6: (ii) | DW6: (iii) | HE6: Revised Values Allocating Collateral Tiers
M7: X | V7: (Used for concentrations) | HE7: First Lien Loan | HG7: Other Type of Loans
A8: CCM ID | B8: Obligor | C8: Security | D8: Loan Type | E8: Type | F8: Non PIK, DIP | G8: Second Lien EBITDA Criteria | H8: Total Leverage Criteria | I8: Acquired Price | J8: USD | K8: Domicile | L8: Cov-lite | M8: Original Maturity | N8: Loan is Not in Payment Default | O8: Agent Approval | P8: Eligible Loan | Q8: Specified Loan | R8: Eligible Obligor | T8: Advance Rate Definition | U8: Advance Rate | V8: Aggregate Adjusted Borrowing Value | W8: Borrower Outstanding Principal Balance | X8: Exchange Rate | Y8: Dollar Equiv Outstanding Principal Balance | Z8: Borrower Facility Commitment | AA8: Dollar Equiv Borrower Facility Commitment | AB8: Dollar Equiv Borrower Unfunded Amount | AC8: Acquisition Price | AE8: FMV | AF8: Applicable Collateral Value | AG8: Value Adjustment Event (Recorded on VAE Tab) | AH8: Event Type | AI8: Material Modification | AJ8: VAE Date | AK8: VAE Agent Assigned Value | AL8: Assigned Value | AO8: First Lien Amount | AP8: Non Eligible First Lien | AQ8: First Lien Value | AU8: FILO Amount | AV8: Non Eligible FILO | AW8: FILO Value | BA8: Second Lien Amount | BD8: Non Eligible Second Lien | BI8: Second Lien Value | BJ8: Check | BK8: Origination Date | BL8: Inclusion Date | BM8: Maturity Date | BN8: PermittedEBITDA ≥$5MM | BO8: PermittedSecond Lien EBITDA ≥$10MM | BP8: Debt-to-Cash Capitalization | BQ8: Eligible Cov-Lite | BR8: S&P Industry | BS8: Cov-Lite? | BT8: Spread | BU8: Delayed Draw Term Loans/Revolver? | BV8: Limited Industries | BW8: Non-Sponsor/ Non-Family Office | BX8: Divdend Recap for Non-Family office/Non-Sponsor | BY8: Fixed Rate? | BZ8: PIK or Partial PIK | CA8: DIP Loans | CB8: CAD Currency | CC8: Interest Paid (Mthly, Qtrly) | CD8: Paid Less than Qtrly | CE8: S&P Rating | CF8: Moody's Rating | CG8: Rated B- or better | CH8: Bid Side Quote | CI8: Relevant Test Period | CJ8: Last Financial Received | CK8: TTM Adjusted | CL8: TTM Non-adjusted EBITDA | CM8: Capped Add-backs | CN8: Add-Backs Percentage | CO8: Add-Back Cap | CP8: Excess Add-backs | CQ8: Agent Add-Back Discretion | CR8: Agent Approved Add-Backs | CS8: Cut Off Permitted TTM EBITDA | CT8: Adjusted EBITDA Haircut | CU8: Current TTM EBITDA | CV8: Inclusion Adj. EBITDA Hiarcut | CW8: Agent Post-Inclusion Adj. Haircut | CX8: Agent Adjusted Addback Haircut | CY8: Current Permitted TTM EBITDA | CZ8: Initial Unrestricted Cash | DA8: Initial Senior Debt | DB8: Initial Total Debt | DC8: Initial Net Senior Leverage in Front of SMC | DD8: Initial Permitted Net Senior leverage | DE8: Initial Permitted Net Total Leverage | DF8: Current Unrestricted Cash | DG8: Current Senior Debt | DH8: Current Total Debt | DI8: Current Net Senior Leverage in Front of SMC | DJ8: VAE Net Senior (Initial if no VAE recorded) | DK8: VAE Net Total (Initial if no VAE recorded) | DL8: Current Net Senior Leverage | DM8: Current Net Total Leverage | DO8: Initial Interest Coverage | DP8: VAE Coverage | DQ8: Current Interest Coverage | DR8: VAE Trigger | DS8: Mths of VAE | DT8: 12 mth VAE | DU8: Cash Interest Coverage Ratio Test | DV8: Net Senior Leverage Ratio Test | DW8: Net Total Leverage Ratio Test | DX8: Obligor Payment Default | DY8: Exercise of Rights and Remedies | DZ8: (a) Reduces/Waives Principal | EA8: (b) Extends Princ./ Interest Payment | EB8: (c) Reduce/ Defer interest | EC8: (d) Subordinates Loan | ED8: (e) Releases Collateral/Lien | EE8: (f) Amends Leverage or IC | EF8: Material Modification | EG8: Obligor Insolvency | EH8: Reporting Failure | EI8: First Lien Advance Rate Class | EJ8: FILO Advance Rate Class | EK8: Dollar Equivalent Adjusted Collateral Value | EL8: Max | EM8: Qualifies? | EN8: Limt | EO8: Excess | EP8: Revised Value | EQ8: Max | ER8: Limt | ES8: Excess | ET8: Revised Value | EU8: Max | EV8: Qualifies? | EW8: loan limit | EX8: Excess | EY8: Revised Value | EZ8: Max | FA8: Qualifies? | FB8: loan limit | FC8: Excess | FD8: Revised Value | FE8: Largest Max | FF8: Second Largest Max | FG8: Third Largest Max | FH8: Max Obligor | FI8: Obligor | FJ8: Remove Dupes | FK8: Rank | FL8: Rank | FM8: Largest Excess | FN8: Second Largest Excess | FO8: Third Largest Excess | FP8: Excess | FQ8: Revised Value | FR8: Max | FS8: Loan Limit | FT8: Largest Industry | FU8: Excess | FV8: Revised Value | FW8: Max | FX8: Loan Limit | FY8: 2nd Largest Industry | FZ8: Excess | GA8: Revised Value | GB8: Max | GC8: Loan Limit | GD8: All Other Industries | GE8: Excess | GF8: Revised Value | GG8: Max | GH8: Loan Limit | GI8: Excess | GJ8: Revised Value | GK8: Max | GL8: Qualifies? | GM8: Loan Limit | GN8: Excess | GO8: Revised Value | GP8: Max | GQ8: Qualifies? | GR8: Loan Limit | GS8: Excess | GT8: Revised Value | GU8: Max | GV8: Qualifies? | GW8: Loan Limit | GX8: Excess | GY8: Revised Value | GZ8: Max | HA8: Qualifies? | HB8: Loan Limit | HC8: Excess | HD8: Revised Value | HE8: First Lien | HG8: FILO | HM8: Second Lien | HN8: check
A9: 1 | B9: =INDEX('Loan Tape - Settled'!$B$4:$AP$55,MATCH($A9,'Loan Tape - Settled'!$E$4:$E$55,0),MATCH("Obligor Name",'Loan Tape - Settled'!$B$4:$AM$4,0)) -> Consolidated Machine & Tool Holdings | C9: =INDEX('Loan Tape - Settled'!$B$4:$AP$55,MATCH($A9,'Loan Tape - Settled'!$E$4:$E$55,0),MATCH("Security",'Loan Tape - Settled'!$B$4:$AM$4,0)) -> 1st Lien | D9: =INDEX('Loan Tape - Settled'!$B$4:$AP$55,MATCH($A9,'Loan Tape - Settled'!$E$4:$E$55,0),MATCH("Loan Type",'Loan Tape - Settled'!$B$4:$AM$4,0)) -> First Lien | E9: =IF(ISERROR(MATCH(D9,AGENT!$A$4:$A$10,0))=FALSE, TRUE) -> TRUE | F9: =IF(AND(BZ9="no",CA9="no"),TRUE) -> TRUE | G9: =IF(D9<>"Second Lien",TRUE, IF(CY9>=AGENT!$B$4,TRUE)) -> TRUE | H9: =IF(DE9<=AGENT!$D$4,TRUE) -> TRUE | I9: =IF(VLOOKUP(CONCATENATE($A$5,A9),'Loan Tape - Settled'!$A$5:$Q$55,17,FALSE)>=AGENT!$E$4,TRUE) -> TRUE | J9: =IF(INDEX('Loan Tape - Settled'!$B$4:$AP$55,MATCH($A9,'Loan Tape - Settled'!$E$4:$E$55,0),MATCH("Loan Denomination",'Loan Tape - Settled'!$B$4:$AP$4,0))="USD", TRUE) -> TRUE | K9: =IF(INDEX('Loan Tape - Settled'!$B$4:$AP$55,MATCH($A9,'Loan Tape - Settled'!$E$4:$E$55,0),MATCH("Exposure Country",'Loan Tape - Settled'!$B$4:$AP$4,0))="United States", TRUE) -> TRUE | L9: =IF(BS9="NO",TRUE) -> TRUE | M9: =IF(((BM9-BL9)/365)<=AGENT!$F$4,TRUE) -> TRUE | N9: =IF(DX9="Yes",FALSE,TRUE) -> FALSE | P9: =IF($B9="","",IF(OR(O9=TRUE,COUNTIFS($E9:$N9,TRUE)=10),"Yes","No")) -> No | Q9: Yes | R9: =IF(P9="Yes",B9,"N/A") -> N/A | T9: {=_xlfn.IFS(D9="Second Lien",D9,D9="First Lien",CONCATENATE(D9," ",EI9),D9="FILO",CONCATENATE(D9," ",EJ9))} -> First Lien <= $10MM | U9: =VLOOKUP(T9,'Concentration Limits'!D:G,4,FALSE) -> 0.625 | V9: =AQ9+AW9+BI9 -> 0 | W9: =(SUMIFS('Loan Tape - Settled'!$AR$4:$AR$55,'Loan Tape - Settled'!$E$4:$E$55,$A9,'Loan Tape - Settled'!$C$4:$C$55,$A$5)) -> 867570.11 | X9: 1 | Y9: =W9*X9 -> 867570.11 | Z9: =(SUMIFS('Loan Tape - Settled'!$AQ$4:$AQ$55,'Loan Tape - Settled'!$E$4:$E$55,$A9,'Loan Tape - Settled'!$C$4:$C$55,$A$5)) -> 867570.11 | AA9: =Z9*X9 -> 867570.11 | AB9: =AA9-Y9 -> 0 | AC9: =VLOOKUP(CONCATENATE($A$5,A9),'Loan Tape - Settled'!$A$5:$Q$55,17,FALSE) -> 1 | AE9: =INDEX('Loan Tape - Settled'!$B$4:$AP$55,MATCH($A9,'Loan Tape - Settled'!$E$4:$E$55,0),MATCH("FMV",'Loan Tape - Settled'!$B$4:$AM$4,0)) -> 0 | AF9: {=_xlfn.IFS(D9="First Lien", _xlfn.IFS(AND(DL9>0,DL9<Tier_1_1L),Tier_1_ApplicableValue, AND(DL9>=Tier_1_1L,DL9<Tier_2_1L),((Tier_1_1L/DL9)*Tier_1_ApplicableValue)+((DL9-Tier_1_1L)/DL9*Tier_2_ApplicableValue), AND(DL9>=Tier_2_1L, DL9<Tier_3_1L),((Tier_1_1L/DL9)*Tier_1_ApplicableValue+(Tier_2_1L-Tier_1_1L)/DL9*Tier_2_ApplicableValue+(DL9-Tier_2_1L)/DL9*Tier_3_ApplicableValue), AND(DL9>=Tier_3_1L, DL9<=Tier_totalzerovalue),((Tier_1_1L/DL9)*Tier_1_ApplicableValue+(Tier_2_1L-Tier_1_1L)/DL9*Tier_2_ApplicableValue+(Tier_3_1L-Tier_2_1L)/DL9*Tier_3_ApplicableValue+(DL9-Tier_partialzerovalue)/DL9*0%), DL9>Tier_totalzerovalue,0%), OR(D9="Second Lien", D9="FILO"), _xlfn.IFS(AND(DM9>0,DM9<Tier_1_2L),Tier_1_ApplicableValue, AND(DM9>=Tier_1_2L,DM9<Tier_2_2L),((Tier_1_2L/DM9)*Tier_1_ApplicableValue)+((DM9-Tier_1_2L)/DM9*Tier_2_ApplicableValue), AND(DM9>=Tier_2_2L, DM9<Tier_3_2L),((Tier_1_2L/DM9)*Tier_1_ApplicableValue+(Tier_2_2L-Tier_1_2L)/DM9*Tier_2_ApplicableValue+(DM9-Tier_2_2L)/DM9*Tier_3_ApplicableValue), AND(DM9>=Tier_3_2L, DM9<=Tier_totalzerovalue),((Tier_1_2L/DM9)*Tier_1_ApplicableValue+(Tier_2_2L-Tier_1_2L)/DM9*Tier_2_ApplicableValue+(Tier_3_2L-Tier_2_2L)/DM9*Tier_3_ApplicableValue+(DM9-Tier_partialzerovalue)/DM9*0%), DM9>Tier_totalzerovalue,0%))} -> 0 | AG9: =IF(COUNTIFS(VAE!$C$5:$C$96,B9,VAE!$G$5:$G$96,"<="&Availability!$F$8)>=1,"Yes","-") -> Yes | AH9: {=IFERROR(IF(AG9="Yes",INDEX(VAE!$D$5:$D$96,MATCH(B9&AJ9,VAE!$C$5:$C$96&VAE!$G$5:$G$96,0)),"-"),0)} -> Increase in Lev | AI9: {=IFERROR(IF(AG9="Yes",INDEX(VAE!$F$5:$F$96,MATCH(B9&AJ9,VAE!$C$5:$C$96&VAE!$G$5:$G$96,0)),"-"),0)} -> n/a | AJ9: =IF(AG9="-","-",_xlfn.MAXIFS(VAE!$G$5:$G$96,VAE!$C$5:$C$96,$B9)) -> 45107 | AK9: {=IFERROR(IF(AG9="Yes",INDEX(VAE!$P$5:$P$96,MATCH(B9&AJ9,VAE!$C$5:$C$96&VAE!$G$5:$G$96,0)),"-"),0)} -> 0 | AL9: =IF($A9="","",IF(P9="No",0,(IF(AG9="Yes",MIN(AE9,AK9,AF9),MIN(AE9,AF9))))) -> 0 | AO9: =IF(AND(D9="First Lien",P9="No"),0,IF(D9<>"First Lien",0,Y9)) -> 0 | AP9: =IF(AND(D9="First Lien",P9="No"),W9,0) -> 867570.11 | AQ9: =AO9*AL9 -> 0 | AU9: =IF(AND(D9="FILO",P9="No"),0,IF(D9<>"FILO",0,Y9)) -> 0 | AV9: =IF(AND(D9="FILO",P9="No"),W9,0) -> 0 | AW9: =AU9*AL9 -> 0 | BA9: =IF(AND(OR(D9="First Lien",D9="FILO"),P9="No"),0,IF(OR(D9="First Lien",D9="FILO"),0,(Y9))) -> 0 | BD9: =IF(AND(D9="Second Lien",P9="No"),W9,0) -> 0 | BI9: =IF(D9="Second Lien",BA9*AL9,0) -> 0 | BJ9: =SUM(AM9:AP9)+SUM(AZ9:BD9)+SUM(AS9:AV9)=Y9 -> TRUE | BK9: =INDEX('Loan Tape - Settled'!$B$4:$AP$55,MATCH($A9,'Loan Tape - Settled'!$E$4:$E$55,0),MATCH("Inception Date",'Loan Tape - Settled'!$B$4:$AP$4,0)) -> 43845 | BL9: =INDEX('Loan Tape - Settled'!$B$4:$AP$55,MATCH($A9,'Loan Tape - Settled'!$E$4:$E$55,0),MATCH("Inclusion Date",'Loan Tape - Settled'!$B$4:$AP$4,0)) -> 44379 | BM9: =INDEX('Loan Tape - Settled'!$B$4:$AP$55,MATCH($A9,'Loan Tape - Settled'!$E$4:$E$55,0),MATCH("Maturity Date",'Loan Tape - Settled'!$B$4:$AP$4,0)) -> 46203 | BR9: =INDEX('Loan Tape - Settled'!$B$4:$AP$55,MATCH($A9,'Loan Tape - Settled'!$E$4:$E$55,0),MATCH("Industry Classification",'Loan Tape - Settled'!$B$4:$AP$4,0)) -> Aerospace & Defense | BS9: =IF(INDEX('Loan Tape - Settled'!$B$4:$AP$55,MATCH($A9,'Loan Tape - Settled'!$E$4:$E$55,0),MATCH("Covenant Lite",'Loan Tape - Settled'!$B$4:$AP$4,0))=-1, "Yes", "No") -> No | BT9: =INDEX('Loan Tape - Settled'!$B$4:$AP$55,MATCH($A9,'Loan Tape - Settled'!$E$4:$E$55,0),MATCH("Spread / Coupon (%)",'Loan Tape - Settled'!$B$4:$AP$4,0)) -> 0.0083704369 | BU9: =IF(INDEX('Loan Tape - Settled'!$B$4:$AP$55,MATCH($A9,'Loan Tape - Settled'!$E$4:$E$55,0),MATCH("Security Type",'Loan Tape - Settled'!$B$4:$AP$4,0))="Delayed Draw Term Loan", "Yes", "No") -> No | BV9: No | BW9: No | BX9: No | BY9: =IF(INDEX('Loan Tape - Settled'!$B$4:$AP$55,MATCH($A9,'Loan Tape - Settled'!$E$4:$E$55,0),MATCH("Fixed/Floating",'Loan Tape - Settled'!$B$4:$AP$4,0))="Fixed", "Yes", "No") -> No | BZ9: No | CA9: No | CB9: =IF(INDEX('Loan Tape - Settled'!$B$4:$AP$55,MATCH($A9,'Loan Tape - Settled'!$E$4:$E$55,0),MATCH("Loan Denomination",'Loan Tape - Settled'!$B$4:$AP$4,0))="CAD", "Yes", "No") -> No | CC9: =INDEX('Loan Tape - Settled'!$B$4:$AP$55,MATCH($A9,'Loan Tape - Settled'!$E$4:$E$55,0),MATCH("Payment Frequency",'Loan Tape - Settled'!$B$4:$AP$4,0)) -> M | CD9: No | CE9: =INDEX('Loan Tape - Settled'!$B$4:$AP$55,MATCH($A9,'Loan Tape - Settled'!$E$4:$E$55,0),MATCH("S&P Loan Rating (if applicable)",'Loan Tape - Settled'!$B$4:$AP$4,0)) -> 0 | CF9: =INDEX('Loan Tape - Settled'!$B$4:$AP$55,MATCH($A9,'Loan Tape - Settled'!$E$4:$E$55,0),MATCH("Moody's Loan Rating (if applicable)",'Loan Tape - Settled'!$B$4:$AP$4,0)) -> 0 | CJ9: =INDEX('Loan Tape - Settled'!$B$4:$BF$55,MATCH($A9,'Loan Tape - Settled'!$E$4:$E$55,0),MATCH("Last Financial Received",'Loan Tape - Settled'!$B$4:$BF$4,0)) -> 9/30/2025 or Latest Financing | CK9: =INDEX('Loan Tape - Settled'!$B$4:$BJ$55,MATCH($A9,'Loan Tape - Settled'!$E$4:$E$55,0),MATCH("Initial Adjusted TTM EBITDA",'Loan Tape - Settled'!$B$4:$BJ$4,0)) -> 6.444 | CL9: =INDEX('Loan Tape - Settled'!$B$4:$BJ$55,MATCH($A9,'Loan Tape - Settled'!$E$4:$E$55,0),MATCH("Initial TTM Non-adjusted EBITDA",'Loan Tape - Settled'!$B$4:$BJ$4,0)) -> 6.444 | CQ9: N | CS9: =CK9-CP9+CR9 -> 6.444 | CT9: =1-CS9/CK9 -> 0 | CU9: =INDEX('Loan Tape - Settled'!$B$4:$BJ$55,MATCH($A9,'Loan Tape - Settled'!$E$4:$E$55,0),MATCH("Current TTM Non-adjusted EBITDA",'Loan Tape - Settled'!$B$4:$BJ$4,0)) -> 0.2906922 | CV9: =CT9 -> 0 | CW9: N | CY9: =IF(CW9="N",(1-CV9)*CU9,(1-CX9)*CU9) -> 0.2906922 | DD9: =INDEX('Loan Tape - Settled'!$B$4:$BJ$55,MATCH($A9,'Loan Tape - Settled'!$E$4:$E$55,0),MATCH("Initial Senior Net Leverage Senior",'Loan Tape - Settled'!$B$4:$BJ$4,0)) -> 2.2031347 | DE9: =INDEX('Loan Tape - Settled'!$B$4:$BJ$55,MATCH($A9,'Loan Tape - Settled'!$E$4:$E$55,0),MATCH("Initial Total Net Leverage",'Loan Tape - Settled'!$B$4:$BJ$4,0)) -> 2.2031347 | DI9: =INDEX('Loan Tape - Settled'!$B$4:$BJ$55,MATCH($A9,'Loan Tape - Settled'!$E$4:$E$55,0),MATCH("Net Attachment",'Loan Tape - Settled'!$B$4:$BJ$4,0)) -> 53.388335 | DJ9: {=IF(AG9="Yes",INDEX(VAE!$M$5:$M$53,MATCH($B9&$AJ9,VAE!$C$5:$C$53&VAE!$G$5:$G$53,0)),DD9)} -> 4.7090319 | DK9: {=IF(AG9="Yes",INDEX(VAE!$N$5:$N$53,MATCH($B9&$AJ9,VAE!$C$5:$C$53&VAE!$G$5:$G$53,0)),DE9)} -> 4.7090319 | DL9: =INDEX('Loan Tape - Settled'!$B$4:$BJ$55,MATCH($A9,'Loan Tape - Settled'!$E$4:$E$55,0),MATCH("Current Senior Net Leverage Senior",'Loan Tape - Settled'!$B$4:$BJ$4,0)) -> N/M | DM9: =INDEX('Loan Tape - Settled'!$B$4:$BJ$55,MATCH($A9,'Loan Tape - Settled'!$E$4:$E$55,0),MATCH("Current Total Net Leverage",'Loan Tape - Settled'!$B$4:$BJ$4,0)) -> N/M | DO9: =INDEX('Loan Tape - Settled'!$B$4:$BJ$55,MATCH($A9,'Loan Tape - Settled'!$E$4:$E$55,0),MATCH("Initial Interest Coverage",'Loan Tape - Settled'!$B$4:$BJ$4,0)) -> 4.05 | DP9: {=IF(AG9="Yes",INDEX(VAE!$O$5:$O$53,MATCH($B9&$AJ9,VAE!$C$5:$C$53&VAE!$G$5:$G$53,0)),DO9)} -> 4.05 | DQ9: =INDEX('Loan Tape - Settled'!$B$4:$BJ$55,MATCH($A9,'Loan Tape - Settled'!$E$4:$E$55,0),MATCH("Current Interest Coverage",'Loan Tape - Settled'!$B$4:$BJ$4,0)) -> 0 | DR9: =IF(OR(DU9="Yes",DU9="N/A",DV9="Yes",DV9="N/A",DW9="Yes",DX9="Yes",DY9="Yes",EF9="Yes",EG9="Yes",EH9="Yes"),"Yes","No") -> Yes | DS9: =IF(AG9="Yes",DATEDIF(AJ9,Availability!$F$8,"m"),"") -> 30 | DT9: =IF(DS9="","No",IF(DS9>12,"Yes","No")) -> Yes | DU9: =IFERROR(IF(AND(DQ9/DP9<0.75,DQ9<1.5),"Yes","No"),"N/A") -> Yes | DV9: =IFERROR(IF(OR(D9="First Lien",D9="FILO"),IF(AND((DL9-DJ9)>0.75,DL9>4),"Yes","No"),"No"),"N/A") -> N/A | DW9: {=_xlfn.IFS(D9<>"Second Lien","No",D9="Second Lien",IF(AND((DM9-DK9)>0.5,DM9>4.5),"Yes","No"))} -> No | DX9: Yes | DY9: No | DZ9: No | EA9: No | EB9: Yes | EC9: No | ED9: No | EE9: No | EF9: =IF(OR(DZ9="Yes",EA9="Yes",EB9="Yes",EC9="Yes",ED9="Yes",EE9="Yes"),"Yes","No") -> Yes | EG9: No | EH9: No | EI9: {=IF(D9="First Lien",_xlfn.IFS(CY9>AGENT!$B$23, "> $20MM",CY9<=AGENT!$C$25, "<= $10MM",AND(CY9<=AGENT!$C$24,CY9>AGENT!$B$24),"<= $20MM"), "N/A")} -> <= $10MM | EJ9: {=IF(D9="FILO",_xlfn.IFS(DI9>AGENT!$B$29, "> 1.25x",DI9<AGENT!$C$27, "< 0.75x",AND(DI9<=AGENT!$C$28,DI9>=AGENT!$B$28),"<= 1.25x"), "N/A")} -> N/A | EK9: =V9 -> 0 | EL9: ='Concentration Limits'!$J$49 -> 46599341 | EM9: =IF(OR(D9="Second Lien",AND(D9="FILO",DI9>AGENT!$C$57)), "Yes", "No") -> No | EN9: =IF(EM9="Yes",SUMIF(EM:EM,"Yes",EK:EK),0) -> 0 | EO9: =IF(EN9>EL9,(EN9-EL9)*(EK9/SUMIF(EM:EM,"Yes",EK:EK)),0) -> 0 | EP9: =MAX(0,EK9-EO9) -> 0 | EQ9: ='Concentration Limits'!$J$50 -> 23299670 | ER9: =IF(D9="Second Lien",SUMIF(D:D,D9,EP:EP),0) -> 0 | ES9: =MAX(0,(ER9-EQ9)*IFERROR((EP9/SUMIF($D:$D,D9,EP:EP )),0) ) -> 0 | ET9: =MAX(0,EP9-ES9) -> 0 | EU9: ='Concentration Limits'!$J$51 -> 69899011 | EV9: =IF(OR(D9="Second Lien", AND(D9="FILO",DI9>AGENT!$C$59)), "Yes", "No") -> No | EW9: =IF(EV9="Yes",SUMIF(EV:EV,"Yes",ET:ET),0) -> 0 | EX9: =IF(EW9>EU9,(EW9-EU9)*(ET9/SUMIF(EV:EV,"Yes",ET:ET)),0) -> 0 | EY9: =MAX(0,ET9-EX9) -> 0 | EZ9: ='Concentration Limits'!$J$52 -> 34949506 | FA9: =IF(CY9>'Concentration Limits'!$E$52, "No", "Yes") -> Yes | FB9: =IF(FA9="Yes",SUMIF(FA:FA,"Yes",EY:EY),0) -> 0 | FC9: =IF(FB9>EZ9,(FB9-EZ9)*(EY9/SUMIF(FA:FA,"Yes",EY:EY)),0) -> 0 | FD9: =MAX(0,EY9-FC9) -> 0 | FE9: ='Concentration Limits'!$J$54 -> 2.329967e+08 | FF9: ='Concentration Limits'!$J$55 -> 2.329967e+08 | FG9: ='Concentration Limits'!$J$56 -> 2.329967e+08 | FH9: ='Concentration Limits'!$J$57 -> 17474753 | FI9: =SUMIF($B:$B,$B9,$FD:$FD) -> 0 | FJ9: =IF(MATCH($B9,$B:$B,0)=ROW(),$FI9,0) -> 0 | FK9: =INDEX(FL$8:FL$60,MATCH(B9,B$8:B$60,0)) -> 0 | FL9: =IF(FJ9>0,RANK(FJ9,$FJ$9:$FJ$60)+COUNTIF($FJ$9:FJ9,FJ9)-1,0) -> 0 | FM9: =IF(FK9=1,IF(FI9>FE9,(FI9-FE9)*(V9/SUMIF($B:$B,B9,$FD:$FD)),0),0) -> 0 | FN9: =IF(FK9=2,IF(FI9>FF9,(FI9-FF9)*(V9/SUMIF($B:$B,B9,$FD:$FD)),0),0) -> 0 | FO9: =IF(FK9=3,IF(FI9>FG9,(FI9-FG9)*(V9/SUMIF($B:$B,B9,$FD:$FD)),0),0) -> 0 | FP9: =IF(FK9>0,IF(FI9>FH9,(FI9-FH9)*(FD9/(SUMIF($B:$B,$B9,$FD:$FD))),0),0) -> 0 | FQ9: =MAX(0,FD9-FM9-FN9-FO9-FP9) -> 0 | FR9: ='Concentration Limits'!$J$58 -> 46599341 | FS9: =SUMIF($BR:$BR,$BR9,FQ:FQ) -> 0 | FT9: =VLOOKUP(BR9,'Concentration Limits'!$E$81:$H$153,4,FALSE) | FU9: =IF(FT9=1,MAX(0,(FS9-FR9)*(FQ9/SUMIF($BR:$BR,BR9,FQ:FQ))),0) -> 0 | FV9: =MAX(0,FQ9-FU9) -> 0 | FW9: ='Concentration Limits'!$J$59 -> 34949506 | FX9: =SUMIF($BR:$BR,$BR9,FV:FV) -> 0 | FY9: =VLOOKUP(BR9,'Concentration Limits'!$E$81:$H$153,4,FALSE) | FZ9: =MAX(0,IF(FY9=2,(FX9-FW9)*(FV9/SUMIF($BR:$BR,BR9,FV:FV)),0)) -> 0 | GA9: =MAX(0,FV9-FZ9) -> 0 | GB9: ='Concentration Limits'!$J$61 -> 23299670 | GC9: =SUMIF($BR:$BR,$BR9,GA:GA) -> 0 | GD9: =VLOOKUP(BR9,'Concentration Limits'!$E$81:$H$153,4,FALSE) | GE9: =IF(GA9=0,0,MAX(0,IF(GD9<3,0,(GC9-GB9)*($GA9/SUMIF($BR:$BR,BR9,GA:GA))))) -> 0 | GF9: =MAX(0,GA9-GE9) -> 0 | GG9: ='Concentration Limits'!$J$64 -> 23299670 | GH9: =IF(BY9="Yes",SUMIF(BY:BY,BY9,GF:GF),0) -> 0 | GI9: =IFERROR(MAX(0,(GH9-GG9)*(GF9/SUMIF($T:$T,T9,GF:GF ))),0) -> 0 | GJ9: =MAX(0,GF9-GI9) -> 0 | GK9: ='Concentration Limits'!$J$67 -> 23299670 | GL9: =IF(OR(BV9="Yes",OR(ISNUMBER(SEARCH("Travel",BR9)),ISNUMBER(SEARCH("Energy",BR9)),ISNUMBER(SEARCH("Leisure",BR9)),ISNUMBER(SEARCH("hotel",BR9)))),"Yes","No") -> No | GM9: =IF(GL9="Yes",SUMIF(GL:GL,"Yes",GJ:GJ),0) -> 0 | GN9: =IF(GM9>GK9,(GM9-GK9)*(GJ9/SUMIF(GL:GL,"Yes",GJ:GJ)),0) -> 0 | GO9: =MAX(0,GJ9-GN9) -> 0 | GP9: ='Concentration Limits'!$J$68 -> 34949506 | GQ9: =IF(BU9="Yes","Yes", "No") -> No | GR9: =IF(GQ9="Yes",SUMIF(GQ:GQ,"Yes",GO:GO),0) -> 0 | GS9: =IF(GR9>GP9,(GR9-GP9)*(GO9/SUMIF(GQ:GQ,"Yes",GO:GO)),0) -> 0 | GT9: =MAX(0,GO9-GS9) -> 0 | GU9: ='Concentration Limits'!$J$69 -> 34949506 | GV9: =IF(BW9="Yes", "Yes", "No") -> No | GW9: =IF(GV9="Yes",SUMIF(GV:GV,"Yes",GT:GT),0) -> 0 | GX9: =IF(GW9>GU9,(GW9-GU9)*(GT9/SUMIF(GV:GV,"Yes",GT:GT)),0) -> 0 | GY9: =MAX(0,GT9-GX9) -> 0 | GZ9: ='Concentration Limits'!$J$70 -> 23299670 | HA9: =IF(BX9="Yes", "Yes", "No") -> No | HB9: =IF(HA9="Yes",SUMIF(HA:HA,"Yes",GY:GY),0) -> 0 | HC9: =IF(HB9>GZ9,(HB9-GZ9)*(GY9/SUMIF(HA:HA,"Yes",GY:GY)),0) -> 0 | HD9: =MAX(0,GY9-HC9) -> 0 | HE9: =IF(AQ9=0,0,HD9*AQ9/(AQ9+AR9)) -> 0 | HF9: =IF(AR9=0,0,HD9*AR9/(AQ9+AR9)) -> 0 | HG9: =IF(AW9=0,0,HD9*AW9/(AW9+AX9)) -> 0 | HH9: =IF(AX9=0,0,HD9*AX9/(AX9+AW9)) -> 0 | HI9: =IF(BE9=0,0,#REF!*BE9/(BE9+BG9)) -> 0 | HJ9: =IF(BG9=0,0,#REF!*BG9/(BG9+BE9)) -> 0 | HK9: =IF(BF9=0,0,#REF!*BF9/(BF9+BH9)) -> 0 | HL9: =IF(BH9=0,0,#REF!*BH9/(BH9+BF9)) -> 0 | HM9: =IF(D9="Second Lien",HD9,0) -> 0 | HN9: =SUM(HE9:HM9)=HD9 -> TRUE
A10: =A9+1 -> 2 | B10: =INDEX('Loan Tape - Settled'!$B$4:$AP$55,MATCH($A10,'Loan Tape - Settled'!$E$4:$E$55,0),MATCH("Obligor Name",'Loan Tape - Settled'!$B$4:$AM$4,0)) -> SkyBell Technologies | C10: =INDEX('Loan Tape - Settled'!$B$4:$AP$55,MATCH($A10,'Loan Tape - Settled'!$E$4:$E$55,0),MATCH("Security",'Loan Tape - Settled'!$B$4:$AM$4,0)) -> 1st Lien | D10: =INDEX('Loan Tape - Settled'!$B$4:$AP$55,MATCH($A10,'Loan Tape - Settled'!$E$4:$E$55,0),MATCH("Loan Type",'Loan Tape - Settled'!$B$4:$AM$4,0)) -> First Lien | E10: =IF(ISERROR(MATCH(D10,AGENT!$A$4:$A$10,0))=FALSE, TRUE) -> TRUE | F10: =IF(AND(BZ10="no",CA10="no"),TRUE) -> TRUE | G10: =IF(D10<>"Second Lien",TRUE, IF(CY10>=AGENT!$B$4,TRUE)) -> TRUE | H10: =IF(DE10<=AGENT!$D$4,TRUE) -> TRUE | I10: =IF(VLOOKUP(CONCATENATE($A$5,A10),'Loan Tape - Settled'!$A$5:$Q$55,17,FALSE)>=AGENT!$E$4,TRUE) -> TRUE | J10: =IF(INDEX('Loan Tape - Settled'!$B$4:$AP$55,MATCH($A10,'Loan Tape - Settled'!$E$4:$E$55,0),MATCH("Loan Denomination",'Loan Tape - Settled'!$B$4:$AP$4,0))="USD", TRUE) -> TRUE | K10: =IF(INDEX('Loan Tape - Settled'!$B$4:$AP$55,MATCH($A10,'Loan Tape - Settled'!$E$4:$E$55,0),MATCH("Exposure Country",'Loan Tape - Settled'!$B$4:$AP$4,0))="United States", TRUE) -> TRUE | L10: =IF(BS10="NO",TRUE) -> TRUE | M10: =IF(((BM10-BL10)/365)<=AGENT!$F$4,TRUE) -> TRUE | N10: =IF(DX10="Yes",FALSE,TRUE) -> FALSE | P10: =IF($B10="","",IF(OR(O10=TRUE,COUNTIFS($E10:$N10,TRUE)=10),"Yes","No")) -> No | Q10: Yes | R10: =IF(P10="Yes",B10,"N/A") -> N/A | T10: {=_xlfn.IFS(D10="Second Lien",D10,D10="First Lien",CONCATENATE(D10," ",EI10),D10="FILO",CONCATENATE(D10," ",EJ10))} -> First Lien <= $10MM | U10: =VLOOKUP(T10,'Concentration Limits'!D:G,4,FALSE) -> 0.625 | V10: =AQ10+AW10+BI10 -> 0 | W10: =(SUMIFS('Loan Tape - Settled'!$AR$4:$AR$55,'Loan Tape - Settled'!$E$4:$E$55,$A10,'Loan Tape - Settled'!$C$4:$C$55,$A$5)) -> 8148216.4 | X10: 1 | Y10: =W10*X10 -> 8148216.4 | Z10: =(SUMIFS('Loan Tape - Settled'!$AQ$4:$AQ$55,'Loan Tape - Settled'!$E$4:$E$55,$A10,'Loan Tape - Settled'!$C$4:$C$55,$A$5)) -> 8148216.4 | AA10: =Z10*X10 -> 8148216.4 | AB10: =AA10-Y10 -> 0 | AC10: =VLOOKUP(CONCATENATE($A$5,A10),'Loan Tape - Settled'!$A$5:$Q$55,17,FALSE) -> 1 | AE10: =INDEX('Loan Tape - Settled'!$B$4:$AP$55,MATCH($A10,'Loan Tape - Settled'!$E$4:$E$55,0),MATCH("FMV",'Loan Tape - Settled'!$B$4:$AM$4,0)) -> 0.842 | AF10: {=_xlfn.IFS(D10="First Lien", _xlfn.IFS(AND(DL10>0,DL10<Tier_1_1L),Tier_1_ApplicableValue, AND(DL10>=Tier_1_1L,DL10<Tier_2_1L),((Tier_1_1L/DL10)*Tier_1_ApplicableValue)+((DL10-Tier_1_1L)/DL10*Tier_2_ApplicableValue), AND(DL10>=Tier_2_1L, DL10<Tier_3_1L),((Tier_1_1L/DL10)*Tier_1_ApplicableValue+(Tier_2_1L-Tier_1_1L)/DL10*Tier_2_ApplicableValue+(DL10-Tier_2_1L)/DL10*Tier_3_ApplicableValue), AND(DL10>=Tier_3_1L, DL10<=Tier_totalzerovalue),((Tier_1_1L/DL10)*Tier_1_ApplicableValue+(Tier_2_1L-Tier_1_1L)/DL10*Tier_2_ApplicableValue+(Tier_3_1L-Tier_2_1L)/DL10*Tier_3_ApplicableValue+(DL10-Tier_partialzerovalue)/DL10*0%), DL10>Tier_totalzerovalue,0%), OR(D10="Second Lien", D10="FILO"), _xlfn.IFS(AND(DM10>0,DM10<Tier_1_2L),Tier_1_ApplicableValue, AND(DM10>=Tier_1_2L,DM10<Tier_2_2L),((Tier_1_2L/DM10)*Tier_1_ApplicableValue)+((DM10-Tier_1_2L)/DM10*Tier_2_ApplicableValue), AND(DM10>=Tier_2_2L, DM10<Tier_3_2L),((Tier_1_2L/DM10)*Tier_1_ApplicableValue+(Tier_2_2L-Tier_1_2L)/DM10*Tier_2_ApplicableValue+(DM10-Tier_2_2L)/DM10*Tier_3_ApplicableValue), AND(DM10>=Tier_3_2L, DM10<=Tier_totalzerovalue),((Tier_1_2L/DM10)*Tier_1_ApplicableValue+(Tier_2_2L-Tier_1_2L)/DM10*Tier_2_ApplicableValue+(Tier_3_2L-Tier_2_2L)/DM10*Tier_3_ApplicableValue+(DM10-Tier_partialzerovalue)/DM10*0%), DM10>Tier_totalzerovalue,0%))} -> 0 | AG10: =IF(COUNTIFS(VAE!$C$5:$C$96,B10,VAE!$G$5:$G$96,"<="&Availability!$F$8)>=1,"Yes","-") -> - | AH10: {=IFERROR(IF(AG10="Yes",INDEX(VAE!$D$5:$D$96,MATCH(B10&AJ10,VAE!$C$5:$C$96&VAE!$G$5:$G$96,0)),"-"),0)} -> - | AI10: {=IFERROR(IF(AG10="Yes",INDEX(VAE!$F$5:$F$96,MATCH(B10&AJ10,VAE!$C$5:$C$96&VAE!$G$5:$G$96,0)),"-"),0)} -> - | AJ10: =IF(AG10="-","-",_xlfn.MAXIFS(VAE!$G$5:$G$96,VAE!$C$5:$C$96,$B10)) -> - | AK10: {=IFERROR(IF(AG10="Yes",INDEX(VAE!$P$5:$P$96,MATCH(B10&AJ10,VAE!$C$5:$C$96&VAE!$G$5:$G$96,0)),"-"),0)} -> - | AL10: =IF($A10="","",IF(P10="No",0,(IF(AG10="Yes",MIN(AE10,AK10,AF10),MIN(AE10,AF10))))) -> 0 | AO10: =IF(AND(D10="First Lien",P10="No"),0,IF(D10<>"First Lien",0,Y10)) -> 0 | AP10: =IF(AND(D10="First Lien",P10="No"),W10,0) -> 8148216.4 | AQ10: =AL10*AO10 -> 0 | AU10: =IF(AND(D10="FILO",P10="No"),0,IF(D10<>"FILO",0,Y10)) -> 0 | AV10: =IF(AND(D10="FILO",P10="No"),W10,0) -> 0 | AW10: =AU10*AL10 -> 0 | BA10: =IF(AND(OR(D10="First Lien",D10="FILO"),P10="No"),0,IF(OR(D10="First Lien",D10="FILO"),0,(Y10))) -> 0 | BD10: =IF(AND(D10="Second Lien",P10="No"),W10,0) -> 0 | BI10: =IF(D10="Second Lien",BA10*AL10,0) -> 0 | BJ10: =SUM(AM10:AP10)+SUM(AZ10:BD10)+SUM(AS10:AV10)=Y10 -> TRUE | BK10: =INDEX('Loan Tape - Settled'!$B$4:$AP$55,MATCH($A10,'Loan Tape - Settled'!$E$4:$E$55,0),MATCH("Inception Date",'Loan Tape - Settled'!$B$4:$AP$4,0)) -> 43812 | BL10: =INDEX('Loan Tape - Settled'!$B$4:$AP$55,MATCH($A10,'Loan Tape - Settled'!$E$4:$E$55,0),MATCH("Inclusion Date",'Loan Tape - Settled'!$B$4:$AP$4,0)) -> 44379 | BM10: =INDEX('Loan Tape - Settled'!$B$4:$AP$55,MATCH($A10,'Loan Tape - Settled'!$E$4:$E$55,0),MATCH("Maturity Date",'Loan Tape - Settled'!$B$4:$AP$4,0)) -> 45639 | BR10: =INDEX('Loan Tape - Settled'!$B$4:$AP$55,MATCH($A10,'Loan Tape - Settled'!$E$4:$E$55,0),MATCH("Industry Classification",'Loan Tape - Settled'!$B$4:$AP$4,0)) -> Household Durables | BS10: =IF(INDEX('Loan Tape - Settled'!$B$4:$AP$55,MATCH($A10,'Loan Tape - Settled'!$E$4:$E$55,0),MATCH("Covenant Lite",'Loan Tape - Settled'!$B$4:$AP$4,0))=-1, "Yes", "No") -> No | BT10: =INDEX('Loan Tape - Settled'!$B$4:$AP$55,MATCH($A10,'Loan Tape - Settled'!$E$4:$E$55,0),MATCH("Spread / Coupon (%)",'Loan Tape - Settled'!$B$4:$AP$4,0)) -> 0 | BU10: =IF(INDEX('Loan Tape - Settled'!$B$4:$AP$55,MATCH($A10,'Loan Tape - Settled'!$E$4:$E$55,0),MATCH("Security Type",'Loan Tape - Settled'!$B$4:$AP$4,0))="Delayed Draw Term Loan", "Yes", "No") -> No | BV10: No | BW10: Yes | BX10: No | BY10: =IF(INDEX('Loan Tape - Settled'!$B$4:$AP$55,MATCH($A10,'Loan Tape - Settled'!$E$4:$E$55,0),MATCH("Fixed/Floating",'Loan Tape - Settled'!$B$4:$AP$4,0))="Fixed", "Yes", "No") -> No | BZ10: No | CA10: No | CB10: =IF(INDEX('Loan Tape - Settled'!$B$4:$AP$55,MATCH($A10,'Loan Tape - Settled'!$E$4:$E$55,0),MATCH("Loan Denomination",'Loan Tape - Settled'!$B$4:$AP$4,0))="CAD", "Yes", "No") -> No | CC10: =INDEX('Loan Tape - Settled'!$B$4:$AP$55,MATCH($A10,'Loan Tape - Settled'!$E$4:$E$55,0),MATCH("Payment Frequency",'Loan Tape - Settled'!$B$4:$AP$4,0)) -> M | CD10: No | CE10: =INDEX('Loan Tape - Settled'!$B$4:$AP$55,MATCH($A10,'Loan Tape - Settled'!$E$4:$E$55,0),MATCH("S&P Loan Rating (if applicable)",'Loan Tape - Settled'!$B$4:$AP$4,0)) -> 0 | CF10: =INDEX('Loan Tape - Settled'!$B$4:$AP$55,MATCH($A10,'Loan Tape - Settled'!$E$4:$E$55,0),MATCH("Moody's Loan Rating (if applicable)",'Loan Tape - Settled'!$B$4:$AP$4,0)) -> 0 | CJ10: =INDEX('Loan Tape - Settled'!$B$4:$BF$55,MATCH($A10,'Loan Tape - Settled'!$E$4:$E$55,0),MATCH("Last Financial Received",'Loan Tape - Settled'!$B$4:$BF$4,0)) -> 9/30/2025 or Latest Financing | CK10: =INDEX('Loan Tape - Settled'!$B$4:$BJ$55,MATCH($A10,'Loan Tape - Settled'!$E$4:$E$55,0),MATCH("Initial Adjusted TTM EBITDA",'Loan Tape - Settled'!$B$4:$BJ$4,0)) -> 9.021 | CL10: =INDEX('Loan Tape - Settled'!$B$4:$BJ$55,MATCH($A10,'Loan Tape - Settled'!$E$4:$E$55,0),MATCH("Initial TTM Non-adjusted EBITDA",'Loan Tape - Settled'!$B$4:$BJ$4,0)) -> 9.021 | CQ10: N | CS10: =CK10-CP10+CR10 -> 9.021 | CT10: =1-CS10/CK10 -> 0 | CU10: =INDEX('Loan Tape - Settled'!$B$4:$BJ$55,MATCH($A10,'Loan Tape - Settled'!$E$4:$E$55,0),MATCH("Current TTM Non-adjusted EBITDA",'Loan Tape - Settled'!$B$4:$BJ$4,0)) -> -8.8045104 | CV10: =CT10 -> 0 | CW10: N | CY10: =IF(CW10="N",(1-CV10)*CU10,(1-CX10)*CU10) -> -8.8045104 | DD10: =INDEX('Loan Tape - Settled'!$B$4:$BJ$55,MATCH($A10,'Loan Tape - Settled'!$E$4:$E$55,0),MATCH("Initial Senior Net Leverage Senior",'Loan Tape - Settled'!$B$4:$BJ$4,0)) -> 2.9138676 | DE10: =INDEX('Loan Tape - Settled'!$B$4:$BJ$55,MATCH($A10,'Loan Tape - Settled'!$E$4:$E$55,0),MATCH("Initial Total Net Leverage",'Loan Tape - Settled'!$B$4:$BJ$4,0)) -> 2.9138676 | DI10: =INDEX('Loan Tape - Settled'!$B$4:$BJ$55,MATCH($A10,'Loan Tape - Settled'!$E$4:$E$55,0),MATCH("Net Attachment",'Loan Tape - Settled'!$B$4:$BJ$4,0)) -> N/A | DJ10: {=IF(AG10="Yes",INDEX(VAE!$M$5:$M$53,MATCH($B10&$AJ10,VAE!$C$5:$C$53&VAE!$G$5:$G$53,0)),DD10)} -> 2.9138676 | DK10: {=IF(AG10="Yes",INDEX(VAE!$N$5:$N$53,MATCH($B10&$AJ10,VAE!$C$5:$C$53&VAE!$G$5:$G$53,0)),DE10)} -> 2.9138676 | DL10: =INDEX('Loan Tape - Settled'!$B$4:$BJ$55,MATCH($A10,'Loan Tape - Settled'!$E$4:$E$55,0),MATCH("Current Senior Net Leverage Senior",'Loan Tape - Settled'!$B$4:$BJ$4,0)) -> N/M | DM10: =INDEX('Loan Tape - Settled'!$B$4:$BJ$55,MATCH($A10,'Loan Tape - Settled'!$E$4:$E$55,0),MATCH("Current Total Net Leverage",'Loan Tape - Settled'!$B$4:$BJ$4,0)) -> N/M | DO10: =INDEX('Loan Tape - Settled'!$B$4:$BJ$55,MATCH($A10,'Loan Tape - Settled'!$E$4:$E$55,0),MATCH("Initial Interest Coverage",'Loan Tape - Settled'!$B$4:$BJ$4,0)) -> 2.31 | DP10: {=IF(AG10="Yes",INDEX(VAE!$O$5:$O$53,MATCH($B10&$AJ10,VAE!$C$5:$C$53&VAE!$G$5:$G$53,0)),DO10)} -> 2.31 | DQ10: =INDEX('Loan Tape - Settled'!$B$4:$BJ$55,MATCH($A10,'Loan Tape - Settled'!$E$4:$E$55,0),MATCH("Current Interest Coverage",'Loan Tape - Settled'!$B$4:$BJ$4,0)) -> 0 | DR10: =IF(OR(DU10="Yes",DU10="N/A",DV10="Yes",DV10="N/A",DW10="Yes",DX10="Yes",DY10="Yes",EF10="Yes",EG10="Yes",EH10="Yes"),"Yes","No") -> Yes | DS10: =IF(AG10="Yes",DATEDIF(AJ10,Availability!$F$8,"m"),"") | DT10: =IF(DS10="","No",IF(DS10>12,"Yes","No")) -> No | DU10: =IFERROR(IF(AND(DQ10/DP10<0.75,DQ10<1.5),"Yes","No"),"N/A") -> Yes | DV10: =IFERROR(IF(OR(D10="First Lien",D10="FILO"),IF(AND((DL10-DJ10)>0.75,DL10>4),"Yes","No"),"No"),"N/A") -> N/A | DW10: {=_xlfn.IFS(D10<>"Second Lien","No",D10="Second Lien",IF(AND((DM10-DK10)>0.5,DM10>4.5),"Yes","No"))} -> No | DX10: Yes | DY10: No | DZ10: Yes | EA10: Yes | EB10: Yes | EC10: No | ED10: No | EE10: No | EF10: =IF(OR(DZ10="Yes",EA10="Yes",EB10="Yes",EC10="Yes",ED10="Yes",EE10="Yes"),"Yes","No") -> Yes | EG10: No | EH10: No | EI10: {=IF(D10="First Lien",_xlfn.IFS(CY10>AGENT!$B$23, "> $20MM",CY10<=AGENT!$C$25, "<= $10MM",AND(CY10<=AGENT!$C$24,CY10>AGENT!$B$24),"<= $20MM"), "N/A")} -> <= $10MM | EJ10: {=IF(D10="FILO",_xlfn.IFS(DI10>AGENT!$B$29, "> 1.25x",DI10<AGENT!$C$27, "< 0.75x",AND(DI10<=AGENT!$C$28,DI10>=AGENT!$B$28),"<= 1.25x"), "N/A")} -> N/A | EK10: =V10 -> 0 | EL10: ='Concentration Limits'!$J$49 -> 46599341 | EM10: =IF(OR(D10="Second Lien",AND(D10="FILO",DI10>AGENT!$C$57)), "Yes", "No") -> No | EN10: =IF(EM10="Yes",SUMIF(EM:EM,"Yes",EK:EK),0) -> 0 | EO10: =IF(EN10>EL10,(EN10-EL10)*(EK10/SUMIF(EM:EM,"Yes",EK:EK)),0) -> 0 | EP10: =MAX(0,EK10-EO10) -> 0 | EQ10: ='Concentration Limits'!$J$50 -> 23299670 | ER10: =IF(D10="Second Lien",SUMIF(D:D,D10,EP:EP),0) -> 0 | ES10: =MAX(0,(ER10-EQ10)*IFERROR((EP10/SUMIF($D:$D,D10,EP:EP )),0) ) -> 0 | ET10: =MAX(0,EP10-ES10) -> 0 | EU10: ='Concentration Limits'!$J$51 -> 69899011 | EV10: =IF(OR(D10="Second Lien", AND(D10="FILO",DI10>AGENT!$C$59)), "Yes", "No") -> No | EW10: =IF(EV10="Yes",SUMIF(EV:EV,"Yes",ET:ET),0) -> 0 | EX10: =IF(EW10>EU10,(EW10-EU10)*(ET10/SUMIF(EV:EV,"Yes",ET:ET)),0) -> 0 | EY10: =MAX(0,ET10-EX10) -> 0 | EZ10: ='Concentration Limits'!$J$52 -> 34949506 | FA10: =IF(CY10>'Concentration Limits'!$E$52, "No", "Yes") -> Yes | FB10: =IF(FA10="Yes",SUMIF(FA:FA,"Yes",EY:EY),0) -> 0 | FC10: =IF(FB10>EZ10,(FB10-EZ10)*(EY10/SUMIF(FA:FA,"Yes",EY:EY)),0) -> 0 | FD10: =MAX(0,EY10-FC10) -> 0 | FE10: ='Concentration Limits'!$J$54 -> 2.329967e+08 | FF10: ='Concentration Limits'!$J$55 -> 2.329967e+08 | FG10: ='Concentration Limits'!$J$56 -> 2.329967e+08 | FH10: ='Concentration Limits'!$J$57 -> 17474753 | FI10: =SUMIF($B:$B,$B10,$FD:$FD) -> 0 | FJ10: =IF(MATCH($B10,$B:$B,0)=ROW(),$FI10,0) -> 0 | FK10: =INDEX(FL$8:FL$60,MATCH(B10,B$8:B$60,0)) -> 0 | FL10: =IF(FJ10>0,RANK(FJ10,$FJ$9:$FJ$60)+COUNTIF($FJ$9:FJ10,FJ10)-1,0) -> 0 | FM10: =IF(FK10=1,IF(FI10>FE10,(FI10-FE10)*(V10/SUMIF($B:$B,B10,$FD:$FD)),0),0) -> 0 | FN10: =IF(FK10=2,IF(FI10>FF10,(FI10-FF10)*(V10/SUMIF($B:$B,B10,$FD:$FD)),0),0) -> 0 | FO10: =IF(FK10=3,IF(FI10>FG10,(FI10-FG10)*(V10/SUMIF($B:$B,B10,$FD:$FD)),0),0) -> 0 | FP10: =IF(FK10>0,IF(FI10>FH10,(FI10-FH10)*(FD10/(SUMIF($B:$B,$B10,$FD:$FD))),0),0) -> 0 | FQ10: =MAX(0,FD10-FM10-FN10-FO10-FP10) -> 0 | FR10: ='Concentration Limits'!$J$58 -> 46599341 | FS10: =SUMIF($BR:$BR,$BR10,FQ:FQ) -> 0 | FT10: =VLOOKUP(BR10,'Concentration Limits'!$E$81:$H$153,4,FALSE) | FU10: =IF(FT10=1,MAX(0,(FS10-FR10)*(FQ10/SUMIF($BR:$BR,BR10,FQ:FQ))),0) -> 0 | FV10: =MAX(0,FQ10-FU10) -> 0 | FW10: ='Concentration Limits'!$J$59 -> 34949506 | FX10: =SUMIF($BR:$BR,$BR10,FV:FV) -> 0 | FY10: =VLOOKUP(BR10,'Concentration Limits'!$E$81:$H$153,4,FALSE) | FZ10: =MAX(0,IF(FY10=2,(FX10-FW10)*(FV10/SUMIF($BR:$BR,BR10,FV:FV)),0)) -> 0 | GA10: =MAX(0,FV10-FZ10) -> 0 | GB10: ='Concentration Limits'!$J$61 -> 23299670 | GC10: =SUMIF($BR:$BR,$BR10,GA:GA) -> 0 | GD10: =VLOOKUP(BR10,'Concentration Limits'!$E$81:$H$153,4,FALSE) | GE10: =IF(GA10=0,0,MAX(0,IF(GD10<3,0,(GC10-GB10)*($GA10/SUMIF($BR:$BR,BR10,GA:GA))))) -> 0 | GF10: =MAX(0,GA10-GE10) -> 0 | GG10: ='Concentration Limits'!$J$64 -> 23299670 | GH10: =IF(BY10="Yes",SUMIF(BY:BY,BY10,GF:GF),0) -> 0 | GI10: =IFERROR(MAX(0,(GH10-GG10)*(GF10/SUMIF($T:$T,T10,GF:GF ))),0) -> 0 | GJ10: =MAX(0,GF10-GI10) -> 0 | GK10: ='Concentration Limits'!$J$67 -> 23299670 | GL10: =IF(OR(BV10="Yes",OR(ISNUMBER(SEARCH("Travel",BR10)),ISNUMBER(SEARCH("Energy",BR10)),ISNUMBER(SEARCH("Leisure",BR10)),ISNUMBER(SEARCH("hotel",BR10)))),"Yes","No") -> No | GM10: =IF(GL10="Yes",SUMIF(GL:GL,"Yes",GJ:GJ),0) -> 0 | GN10: =IF(GM10>GK10,(GM10-GK10)*(GJ10/SUMIF(GL:GL,"Yes",GJ:GJ)),0) -> 0 | GO10: =MAX(0,GJ10-GN10) -> 0 | GP10: ='Concentration Limits'!$J$68 -> 34949506 | GQ10: =IF(BU10="Yes","Yes", "No") -> No | GR10: =IF(GQ10="Yes",SUMIF(GQ:GQ,"Yes",GO:GO),0) -> 0 | GS10: =IF(GR10>GP10,(GR10-GP10)*(GO10/SUMIF(GQ:GQ,"Yes",GO:GO)),0) -> 0 | GT10: =MAX(0,GO10-GS10) -> 0 | GU10: ='Concentration Limits'!$J$69 -> 34949506 | GV10: =IF(BW10="Yes", "Yes", "No") -> Yes | GW10: =IF(GV10="Yes",SUMIF(GV:GV,"Yes",GT:GT),0) -> 12656118 | GX10: =IF(GW10>GU10,(GW10-GU10)*(GT10/SUMIF(GV:GV,"Yes",GT:GT)),0) -> 0 | GY10: =MAX(0,GT10-GX10) -> 0 | GZ10: ='Concentration Limits'!$J$70 -> 23299670 | HA10: =IF(BX10="Yes", "Yes", "No") -> No | HB10: =IF(HA10="Yes",SUMIF(HA:HA,"Yes",GY:GY),0) -> 0 | HC10: =IF(HB10>GZ10,(HB10-GZ10)*(GY10/SUMIF(HA:HA,"Yes",GY:GY)),0) -> 0 | HD10: =MAX(0,GY10-HC10) -> 0 | HE10: =IF(AQ10=0,0,HD10*AQ10/(AQ10+AR10)) -> 0 | HF10: =IF(AR10=0,0,HD10*AR10/(AQ10+AR10)) -> 0 | HG10: =IF(AW10=0,0,HD10*AW10/(AW10+AX10)) -> 0 | HH10: =IF(AX10=0,0,HD10*AX10/(AX10+AW10)) -> 0 | HI10: =IF(BE10=0,0,#REF!*BE10/(BE10+BG10)) -> 0 | HJ10: =IF(BG10=0,0,#REF!*BG10/(BG10+BE10)) -> 0 | HK10: =IF(BF10=0,0,#REF!*BF10/(BF10+BH10)) -> 0 | HL10: =IF(BH10=0,0,#REF!*BH10/(BH10+BF10)) -> 0 | HM10: =IF(D10="Second Lien",HD10,0) -> 0 | HN10: =SUM(HE10:HM10)=HD10 -> TRUE
A11: =A10+1 -> 3 | B11: =INDEX('Loan Tape - Settled'!$B$4:$AP$55,MATCH($A11,'Loan Tape - Settled'!$E$4:$E$55,0),MATCH("Obligor Name",'Loan Tape - Settled'!$B$4:$AM$4,0)) -> Microf | C11: =INDEX('Loan Tape - Settled'!$B$4:$AP$55,MATCH($A11,'Loan Tape - Settled'!$E$4:$E$55,0),MATCH("Security",'Loan Tape - Settled'!$B$4:$AM$4,0)) -> 1st Lien | D11: =INDEX('Loan Tape - Settled'!$B$4:$AP$55,MATCH($A11,'Loan Tape - Settled'!$E$4:$E$55,0),MATCH("Loan Type",'Loan Tape - Settled'!$B$4:$AM$4,0)) -> First Lien | E11: =IF(ISERROR(MATCH(D11,AGENT!$A$4:$A$10,0))=FALSE, TRUE) -> TRUE | F11: =IF(AND(BZ11="no",CA11="no"),TRUE) -> TRUE | G11: =IF(D11<>"Second Lien",TRUE, IF(CY11>=AGENT!$B$4,TRUE)) -> TRUE | H11: =IF(DE11<=AGENT!$D$4,TRUE) -> TRUE | I11: =IF(VLOOKUP(CONCATENATE($A$5,A11),'Loan Tape - Settled'!$A$5:$Q$55,17,FALSE)>=AGENT!$E$4,TRUE) -> TRUE | J11: =IF(INDEX('Loan Tape - Settled'!$B$4:$AP$55,MATCH($A11,'Loan Tape - Settled'!$E$4:$E$55,0),MATCH("Loan Denomination",'Loan Tape - Settled'!$B$4:$AP$4,0))="USD", TRUE) -> TRUE | K11: =IF(INDEX('Loan Tape - Settled'!$B$4:$AP$55,MATCH($A11,'Loan Tape - Settled'!$E$4:$E$55,0),MATCH("Exposure Country",'Loan Tape - Settled'!$B$4:$AP$4,0))="United States", TRUE) -> TRUE | L11: =IF(BS11="NO",TRUE) -> TRUE | M11: =IF(((BM11-BL11)/365)<=AGENT!$F$4,TRUE) -> TRUE | N11: =IF(DX11="Yes",FALSE,TRUE) -> FALSE | P11: =IF($B11="","",IF(OR(O11=TRUE,COUNTIFS($E11:$N11,TRUE)=10),"Yes","No")) -> No | Q11: Yes | R11: =IF(P11="Yes",B11,"N/A") -> N/A | T11: {=_xlfn.IFS(D11="Second Lien",D11,D11="First Lien",CONCATENATE(D11," ",EI11),D11="FILO",CONCATENATE(D11," ",EJ11))} -> First Lien > $20MM | U11: =VLOOKUP(T11,'Concentration Limits'!D:G,4,FALSE) -> 0.675 | V11: =AQ11+AW11+BI11 -> 0 | W11: =(SUMIFS('Loan Tape - Settled'!$AR$4:$AR$55,'Loan Tape - Settled'!$E$4:$E$55,$A11,'Loan Tape - Settled'!$C$4:$C$55,$A$5)) -> 3714428.9 | X11: 1 | Y11: =W11*X11 -> 3714428.9 | Z11: =(SUMIFS('Loan Tape - Settled'!$AQ$4:$AQ$55,'Loan Tape - Settled'!$E$4:$E$55,$A11,'Loan Tape - Settled'!$C$4:$C$55,$A$5)) -> 3714428.9 | AA11: =Z11*X11 -> 3714428.9 | AB11: =AA11-Y11 -> 0 | AC11: =VLOOKUP(CONCATENATE($A$5,A11),'Loan Tape - Settled'!$A$5:$Q$55,17,FALSE) -> 1 | AE11: =INDEX('Loan Tape - Settled'!$B$4:$AP$55,MATCH($A11,'Loan Tape - Settled'!$E$4:$E$55,0),MATCH("FMV",'Loan Tape - Settled'!$B$4:$AM$4,0)) -> 1.0011 | AF11: {=_xlfn.IFS(D11="First Lien", _xlfn.IFS(AND(DL11>0,DL11<Tier_1_1L),Tier_1_ApplicableValue, AND(DL11>=Tier_1_1L,DL11<Tier_2_1L),((Tier_1_1L/DL11)*Tier_1_ApplicableValue)+((DL11-Tier_1_1L)/DL11*Tier_2_ApplicableValue), AND(DL11>=Tier_2_1L, DL11<Tier_3_1L),((Tier_1_1L/DL11)*Tier_1_ApplicableValue+(Tier_2_1L-Tier_1_1L)/DL11*Tier_2_ApplicableValue+(DL11-Tier_2_1L)/DL11*Tier_3_ApplicableValue), AND(DL11>=Tier_3_1L, DL11<=Tier_totalzerovalue),((Tier_1_1L/DL11)*Tier_1_ApplicableValue+(Tier_2_1L-Tier_1_1L)/DL11*Tier_2_ApplicableValue+(Tier_3_1L-Tier_2_1L)/DL11*Tier_3_ApplicableValue+(DL11-Tier_partialzerovalue)/DL11*0%), DL11>Tier_totalzerovalue,0%), OR(D11="Second Lien", D11="FILO"), _xlfn.IFS(AND(DM11>0,DM11<Tier_1_2L),Tier_1_ApplicableValue, AND(DM11>=Tier_1_2L,DM11<Tier_2_2L),((Tier_1_2L/DM11)*Tier_1_ApplicableValue)+((DM11-Tier_1_2L)/DM11*Tier_2_ApplicableValue), AND(DM11>=Tier_2_2L, DM11<Tier_3_2L),((Tier_1_2L/DM11)*Tier_1_ApplicableValue+(Tier_2_2L-Tier_1_2L)/DM11*Tier_2_ApplicableValue+(DM11-Tier_2_2L)/DM11*Tier_3_ApplicableValue), AND(DM11>=Tier_3_2L, DM11<=Tier_totalzerovalue),((Tier_1_2L/DM11)*Tier_1_ApplicableValue+(Tier_2_2L-Tier_1_2L)/DM11*Tier_2_ApplicableValue+(Tier_3_2L-Tier_2_2L)/DM11*Tier_3_ApplicableValue+(DM11-Tier_partialzerovalue)/DM11*0%), DM11>Tier_totalzerovalue,0%))} -> 1 | AG11: =IF(COUNTIFS(VAE!$C$5:$C$96,B11,VAE!$G$5:$G$96,"<="&Availability!$F$8)>=1,"Yes","-") -> Yes | AH11: {=IFERROR(IF(AG11="Yes",INDEX(VAE!$D$5:$D$96,MATCH(B11&AJ11,VAE!$C$5:$C$96&VAE!$G$5:$G$96,0)),"-"),0)} -> Obligor payment default | AI11: {=IFERROR(IF(AG11="Yes",INDEX(VAE!$F$5:$F$96,MATCH(B11&AJ11,VAE!$C$5:$C$96&VAE!$G$5:$G$96,0)),"-"),0)} -> n/a | AJ11: =IF(AG11="-","-",_xlfn.MAXIFS(VAE!$G$5:$G$96,VAE!$C$5:$C$96,$B11)) -> 45473 | AK11: {=IFERROR(IF(AG11="Yes",INDEX(VAE!$P$5:$P$96,MATCH(B11&AJ11,VAE!$C$5:$C$96&VAE!$G$5:$G$96,0)),"-"),0)} -> 0 | AL11: =IF($A11="","",IF(P11="No",0,(IF(AG11="Yes",MIN(AE11,AK11,AF11),MIN(AE11,AF11))))) -> 0 | AO11: =IF(AND(D11="First Lien",P11="No"),0,IF(D11<>"First Lien",0,Y11)) -> 0 | AP11: =IF(AND(D11="First Lien",P11="No"),W11,0) -> 3714428.9 | AQ11: =AL11*AO11 -> 0 | AU11: =IF(AND(D11="FILO",P11="No"),0,IF(D11<>"FILO",0,Y11)) -> 0 | AV11: =IF(AND(D11="FILO",P11="No"),W11,0) -> 0 | AW11: =AU11*AL11 -> 0 | BA11: =IF(AND(OR(D11="First Lien",D11="FILO"),P11="No"),0,IF(OR(D11="First Lien",D11="FILO"),0,(Y11))) -> 0 | BD11: =IF(AND(D11="Second Lien",P11="No"),W11,0) -> 0 | BI11: =IF(D11="Second Lien",BA11*AL11,0) -> 0 | BJ11: =SUM(AM11:AP11)+SUM(AZ11:BD11)+SUM(AS11:AV11)=Y11 -> TRUE | BK11: =INDEX('Loan Tape - Settled'!$B$4:$AP$55,MATCH($A11,'Loan Tape - Settled'!$E$4:$E$55,0),MATCH("Inception Date",'Loan Tape - Settled'!$B$4:$AP$4,0)) -> 43553 | BL11: =INDEX('Loan Tape - Settled'!$B$4:$AP$55,MATCH($A11,'Loan Tape - Settled'!$E$4:$E$55,0),MATCH("Inclusion Date",'Loan Tape - Settled'!$B$4:$AP$4,0)) -> 44379 | BM11: =INDEX('Loan Tape - Settled'!$B$4:$AP$55,MATCH($A11,'Loan Tape - Settled'!$E$4:$E$55,0),MATCH("Maturity Date",'Loan Tape - Settled'!$B$4:$AP$4,0)) -> 46721 | BR11: =INDEX('Loan Tape - Settled'!$B$4:$AP$55,MATCH($A11,'Loan Tape - Settled'!$E$4:$E$55,0),MATCH("Industry Classification",'Loan Tape - Settled'!$B$4:$AP$4,0)) -> Consumer Finance | BS11: =IF(INDEX('Loan Tape - Settled'!$B$4:$AP$55,MATCH($A11,'Loan Tape - Settled'!$E$4:$E$55,0),MATCH("Covenant Lite",'Loan Tape - Settled'!$B$4:$AP$4,0))=-1, "Yes", "No") -> No | BT11: =INDEX('Loan Tape - Settled'!$B$4:$AP$55,MATCH($A11,'Loan Tape - Settled'!$E$4:$E$55,0),MATCH("Spread / Coupon (%)",'Loan Tape - Settled'!$B$4:$AP$4,0)) -> 0.1085 | BU11: =IF(INDEX('Loan Tape - Settled'!$B$4:$AP$55,MATCH($A11,'Loan Tape - Settled'!$E$4:$E$55,0),MATCH("Security Type",'Loan Tape - Settled'!$B$4:$AP$4,0))="Delayed Draw Term Loan", "Yes", "No") -> No | BV11: No | BW11: No | BX11: No | BY11: =IF(INDEX('Loan Tape - Settled'!$B$4:$AP$55,MATCH($A11,'Loan Tape - Settled'!$E$4:$E$55,0),MATCH("Fixed/Floating",'Loan Tape - Settled'!$B$4:$AP$4,0))="Fixed", "Yes", "No") -> No | BZ11: No | CA11: No | CB11: =IF(INDEX('Loan Tape - Settled'!$B$4:$AP$55,MATCH($A11,'Loan Tape - Settled'!$E$4:$E$55,0),MATCH("Loan Denomination",'Loan Tape - Settled'!$B$4:$AP$4,0))="CAD", "Yes", "No") -> No | CC11: =INDEX('Loan Tape - Settled'!$B$4:$AP$55,MATCH($A11,'Loan Tape - Settled'!$E$4:$E$55,0),MATCH("Payment Frequency",'Loan Tape - Settled'!$B$4:$AP$4,0)) -> M | CD11: No | CE11: =INDEX('Loan Tape - Settled'!$B$4:$AP$55,MATCH($A11,'Loan Tape - Settled'!$E$4:$E$55,0),MATCH("S&P Loan Rating (if applicable)",'Loan Tape - Settled'!$B$4:$AP$4,0)) -> 0 | CF11: =INDEX('Loan Tape - Settled'!$B$4:$AP$55,MATCH($A11,'Loan Tape - Settled'!$E$4:$E$55,0),MATCH("Moody's Loan Rating (if applicable)",'Loan Tape - Settled'!$B$4:$AP$4,0)) -> 0 | CJ11: =INDEX('Loan Tape - Settled'!$B$4:$BF$55,MATCH($A11,'Loan Tape - Settled'!$E$4:$E$55,0),MATCH("Last Financial Received",'Loan Tape - Settled'!$B$4:$BF$4,0)) -> 9/30/2025 or Latest Financing | CK11: =INDEX('Loan Tape - Settled'!$B$4:$BJ$55,MATCH($A11,'Loan Tape - Settled'!$E$4:$E$55,0),MATCH("Initial Adjusted TTM EBITDA",'Loan Tape - Settled'!$B$4:$BJ$4,0)) -> 3.818 | CL11: =INDEX('Loan Tape - Settled'!$B$4:$BJ$55,MATCH($A11,'Loan Tape - Settled'!$E$4:$E$55,0),MATCH("Initial TTM Non-adjusted EBITDA",'Loan Tape - Settled'!$B$4:$BJ$4,0)) -> 3.818 | CQ11: N | CS11: =CK11-CP11+CR11 -> 3.818 | CT11: =1-CS11/CK11 -> 0 | CU11: =INDEX('Loan Tape - Settled'!$B$4:$BJ$55,MATCH($A11,'Loan Tape - Settled'!$E$4:$E$55,0),MATCH("Current TTM Non-adjusted EBITDA",'Loan Tape - Settled'!$B$4:$BJ$4,0)) -> 27.080543 | CV11: =CT11 -> 0 | CW11: N | CY11: =IF(CW11="N",(1-CV11)*CU11,(1-CX11)*CU11) -> 27.080543 | DD11: =INDEX('Loan Tape - Settled'!$B$4:$BJ$55,MATCH($A11,'Loan Tape - Settled'!$E$4:$E$55,0),MATCH("Initial Senior Net Leverage Senior",'Loan Tape - Settled'!$B$4:$BJ$4,0)) -> 4 | DE11: =INDEX('Loan Tape - Settled'!$B$4:$BJ$55,MATCH($A11,'Loan Tape - Settled'!$E$4:$E$55,0),MATCH("Initial Total Net Leverage",'Loan Tape - Settled'!$B$4:$BJ$4,0)) -> 4 | DI11: =INDEX('Loan Tape - Settled'!$B$4:$BJ$55,MATCH($A11,'Loan Tape - Settled'!$E$4:$E$55,0),MATCH("Net Attachment",'Loan Tape - Settled'!$B$4:$BJ$4,0)) -> 2.0341469 | DJ11: {=IF(AG11="Yes",INDEX(VAE!$M$5:$M$53,MATCH($B11&$AJ11,VAE!$C$5:$C$53&VAE!$G$5:$G$53,0)),DD11)} -> - | DK11: {=IF(AG11="Yes",INDEX(VAE!$N$5:$N$53,MATCH($B11&$AJ11,VAE!$C$5:$C$53&VAE!$G$5:$G$53,0)),DE11)} -> - | DL11: =INDEX('Loan Tape - Settled'!$B$4:$BJ$55,MATCH($A11,'Loan Tape - Settled'!$E$4:$E$55,0),MATCH("Current Senior Net Leverage Senior",'Loan Tape - Settled'!$B$4:$BJ$4,0)) -> 3.0685633 | DM11: =INDEX('Loan Tape - Settled'!$B$4:$BJ$55,MATCH($A11,'Loan Tape - Settled'!$E$4:$E$55,0),MATCH("Current Total Net Leverage",'Loan Tape - Settled'!$B$4:$BJ$4,0)) -> 3.0685633 | DO11: =INDEX('Loan Tape - Settled'!$B$4:$BJ$55,MATCH($A11,'Loan Tape - Settled'!$E$4:$E$55,0),MATCH("Initial Interest Coverage",'Loan Tape - Settled'!$B$4:$BJ$4,0)) -> 2.39 | DP11: {=IF(AG11="Yes",INDEX(VAE!$O$5:$O$53,MATCH($B11&$AJ11,VAE!$C$5:$C$53&VAE!$G$5:$G$53,0)),DO11)} -> 0 | DQ11: =INDEX('Loan Tape - Settled'!$B$4:$BJ$55,MATCH($A11,'Loan Tape - Settled'!$E$4:$E$55,0),MATCH("Current Interest Coverage",'Loan Tape - Settled'!$B$4:$BJ$4,0)) -> 2.7739952 | DR11: =IF(OR(DU11="Yes",DU11="N/A",DV11="Yes",DV11="N/A",DW11="Yes",DX11="Yes",DY11="Yes",EF11="Yes",EG11="Yes",EH11="Yes"),"Yes","No") -> Yes | DS11: =IF(AG11="Yes",DATEDIF(AJ11,Availability!$F$8,"m"),"") -> 18 | DT11: =IF(DS11="","No",IF(DS11>12,"Yes","No")) -> Yes | DU11: =IFERROR(IF(AND(DQ11/DP11<0.75,DQ11<1.5),"Yes","No"),"N/A") -> N/A | DV11: =IFERROR(IF(OR(D11="First Lien",D11="FILO"),IF(AND((DL11-DJ11)>0.75,DL11>4),"Yes","No"),"No"),"N/A") -> N/A | DW11: {=_xlfn.IFS(D11<>"Second Lien","No",D11="Second Lien",IF(AND((DM11-DK11)>0.5,DM11>4.5),"Yes","No"))} -> No | DX11: Yes | DY11: No | DZ11: No | EA11: No | EB11: Yes | EC11: No | ED11: No | EE11: No | EF11: =IF(OR(DZ11="Yes",EA11="Yes",EB11="Yes",EC11="Yes",ED11="Yes",EE11="Yes"),"Yes","No") -> Yes | EG11: No | EH11: No | EI11: {=IF(D11="First Lien",_xlfn.IFS(CY11>AGENT!$B$23, "> $20MM",CY11<=AGENT!$C$25, "<= $10MM",AND(CY11<=AGENT!$C$24,CY11>AGENT!$B$24),"<= $20MM"), "N/A")} -> > $20MM | EJ11: {=IF(D11="FILO",_xlfn.IFS(DI11>AGENT!$B$29, "> 1.25x",DI11<AGENT!$C$27, "< 0.75x",AND(DI11<=AGENT!$C$28,DI11>=AGENT!$B$28),"<= 1.25x"), "N/A")} -> N/A | EK11: =V11 -> 0 | EL11: ='Concentration Limits'!$J$49 -> 46599341 | EM11: =IF(OR(D11="Second Lien",AND(D11="FILO",DI11>AGENT!$C$57)), "Yes", "No") -> No | EN11: =IF(EM11="Yes",SUMIF(EM:EM,"Yes",EK:EK),0) -> 0 | EO11: =IF(EN11>EL11,(EN11-EL11)*(EK11/SUMIF(EM:EM,"Yes",EK:EK)),0) -> 0 | EP11: =MAX(0,EK11-EO11) -> 0 | EQ11: ='Concentration Limits'!$J$50 -> 23299670 | ER11: =IF(D11="Second Lien",SUMIF(D:D,D11,EP:EP),0) -> 0 | ES11: =MAX(0,(ER11-EQ11)*IFERROR((EP11/SUMIF($D:$D,D11,EP:EP )),0) ) -> 0 | ET11: =MAX(0,EP11-ES11) -> 0 | EU11: ='Concentration Limits'!$J$51 -> 69899011 | EV11: =IF(OR(D11="Second Lien", AND(D11="FILO",DI11>AGENT!$C$59)), "Yes", "No") -> No | EW11: =IF(EV11="Yes",SUMIF(EV:EV,"Yes",ET:ET),0) -> 0 | EX11: =IF(EW11>EU11,(EW11-EU11)*(ET11/SUMIF(EV:EV,"Yes",ET:ET)),0) -> 0 | EY11: =MAX(0,ET11-EX11) -> 0 | EZ11: ='Concentration Limits'!$J$52 -> 34949506 | FA11: =IF(CY11>'Concentration Limits'!$E$52, "No", "Yes") -> No | FB11: =IF(FA11="Yes",SUMIF(FA:FA,"Yes",EY:EY),0) -> 0 | FC11: =IF(FB11>EZ11,(FB11-EZ11)*(EY11/SUMIF(FA:FA,"Yes",EY:EY)),0) -> 0 | FD11: =MAX(0,EY11-FC11) -> 0 | FE11: ='Concentration Limits'!$J$54 -> 2.329967e+08 | FF11: ='Concentration Limits'!$J$55 -> 2.329967e+08 | FG11: ='Concentration Limits'!$J$56 -> 2.329967e+08 | FH11: ='Concentration Limits'!$J$57 -> 17474753 | FI11: =SUMIF($B:$B,$B11,$FD:$FD) -> 0 | FJ11: =IF(MATCH($B11,$B:$B,0)=ROW(),$FI11,0) -> 0 | FK11: =INDEX(FL$8:FL$60,MATCH(B11,B$8:B$60,0)) -> 0 | FL11: =IF(FJ11>0,RANK(FJ11,$FJ$9:$FJ$60)+COUNTIF($FJ$9:FJ11,FJ11)-1,0) -> 0 | FM11: =IF(FK11=1,IF(FI11>FE11,(FI11-FE11)*(V11/SUMIF($B:$B,B11,$FD:$FD)),0),0) -> 0 | FN11: =IF(FK11=2,IF(FI11>FF11,(FI11-FF11)*(V11/SUMIF($B:$B,B11,$FD:$FD)),0),0) -> 0 | FO11: =IF(FK11=3,IF(FI11>FG11,(FI11-FG11)*(V11/SUMIF($B:$B,B11,$FD:$FD)),0),0) -> 0 | FP11: =IF(FK11>0,IF(FI11>FH11,(FI11-FH11)*(FD11/(SUMIF($B:$B,$B11,$FD:$FD))),0),0) -> 0 | FQ11: =MAX(0,FD11-FM11-FN11-FO11-FP11) -> 0 | FR11: ='Concentration Limits'!$J$58 -> 46599341 | FS11: =SUMIF($BR:$BR,$BR11,FQ:FQ) -> 0 | FT11: =VLOOKUP(BR11,'Concentration Limits'!$E$81:$H$153,4,FALSE) | FU11: =IF(FT11=1,MAX(0,(FS11-FR11)*(FQ11/SUMIF($BR:$BR,BR11,FQ:FQ))),0) -> 0 | FV11: =MAX(0,FQ11-FU11) -> 0 | FW11: ='Concentration Limits'!$J$59 -> 34949506 | FX11: =SUMIF($BR:$BR,$BR11,FV:FV) -> 0 | FY11: =VLOOKUP(BR11,'Concentration Limits'!$E$81:$H$153,4,FALSE) | FZ11: =MAX(0,IF(FY11=2,(FX11-FW11)*(FV11/SUMIF($BR:$BR,BR11,FV:FV)),0)) -> 0 | GA11: =MAX(0,FV11-FZ11) -> 0 | GB11: ='Concentration Limits'!$J$61 -> 23299670 | GC11: =SUMIF($BR:$BR,$BR11,GA:GA) -> 0 | GD11: =VLOOKUP(BR11,'Concentration Limits'!$E$81:$H$153,4,FALSE) | GE11: =IF(GA11=0,0,MAX(0,IF(GD11<3,0,(GC11-GB11)*($GA11/SUMIF($BR:$BR,BR11,GA:GA))))) -> 0 | GF11: =MAX(0,GA11-GE11) -> 0 | GG11: ='Concentration Limits'!$J$64 -> 23299670 | GH11: =IF(BY11="Yes",SUMIF(BY:BY,BY11,GF:GF),0) -> 0 | GI11: =IFERROR(MAX(0,(GH11-GG11)*(GF11/SUMIF($T:$T,T11,GF:GF ))),0) -> 0 | GJ11: =MAX(0,GF11-GI11) -> 0 | GK11: ='Concentration Limits'!$J$67 -> 23299670 | GL11: =IF(OR(BV11="Yes",OR(ISNUMBER(SEARCH("Travel",BR11)),ISNUMBER(SEARCH("Energy",BR11)),ISNUMBER(SEARCH("Leisure",BR11)),ISNUMBER(SEARCH("hotel",BR11)))),"Yes","No") -> No | GM11: =IF(GL11="Yes",SUMIF(GL:GL,"Yes",GJ:GJ),0) -> 0 | GN11: =IF(GM11>GK11,(GM11-GK11)*(GJ11/SUMIF(GL:GL,"Yes",GJ:GJ)),0) -> 0 | GO11: =MAX(0,GJ11-GN11) -> 0 | GP11: ='Concentration Limits'!$J$68 -> 34949506 | GQ11: =IF(BU11="Yes","Yes", "No") -> No | GR11: =IF(GQ11="Yes",SUMIF(GQ:GQ,"Yes",GO:GO),0) -> 0 | GS11: =IF(GR11>GP11,(GR11-GP11)*(GO11/SUMIF(GQ:GQ,"Yes",GO:GO)),0) -> 0 | GT11: =MAX(0,GO11-GS11) -> 0 | GU11: ='Concentration Limits'!$J$69 -> 34949506 | GV11: =IF(BW11="Yes", "Yes", "No") -> No | GW11: =IF(GV11="Yes",SUMIF(GV:GV,"Yes",GT:GT),0) -> 0 | GX11: =IF(GW11>GU11,(GW11-GU11)*(GT11/SUMIF(GV:GV,"Yes",GT:GT)),0) -> 0 | GY11: =MAX(0,GT11-GX11) -> 0 | GZ11: ='Concentration Limits'!$J$70 -> 23299670 | HA11: =IF(BX11="Yes", "Yes", "No") -> No | HB11: =IF(HA11="Yes",SUMIF(HA:HA,"Yes",GY:GY),0) -> 0 | HC11: =IF(HB11>GZ11,(HB11-GZ11)*(GY11/SUMIF(HA:HA,"Yes",GY:GY)),0) -> 0 | HD11: =MAX(0,GY11-HC11) -> 0 | HE11: =IF(AQ11=0,0,HD11*AQ11/(AQ11+AR11)) -> 0 | HF11: =IF(AR11=0,0,HD11*AR11/(AQ11+AR11)) -> 0 | HG11: =IF(AW11=0,0,HD11*AW11/(AW11+AX11)) -> 0 | HH11: =IF(AX11=0,0,HD11*AX11/(AX11+AW11)) -> 0 | HI11: =IF(BE11=0,0,#REF!*BE11/(BE11+BG11)) -> 0 | HJ11: =IF(BG11=0,0,#REF!*BG11/(BG11+BE11)) -> 0 | HK11: =IF(BF11=0,0,#REF!*BF11/(BF11+BH11)) -> 0 | HL11: =IF(BH11=0,0,#REF!*BH11/(BH11+BF11)) -> 0 | HM11: =IF(D11="Second Lien",HD11,0) -> 0 | HN11: =SUM(HE11:HM11)=HD11 -> TRUE
